Workbook

Sheet Konfig
B2: KONFIGURATION
B4: NØGLETAL
B5: Value per customer (kr.) | C5: 1000 | D5: Estimeret livstidsværdi pr. kunde
B6: Timepris partnerskab (kr.) | C6: 800 | D6: Kontrakteret timepris til Meliora Ventures
B7: CMO omkostning (kr./md.) | C7: 24000 | D7: 80% allokeret til partnerskabs-kanal (30.000 * 0,8)
B8: Kontrakterede timer (total) | C8: 700 | D8: Samlet contracted hours i nuværende aftale
B9: Mål-CAC (kr.) | C9: 500 | D9: Acceptabel CAC pr. nye kunde
B10: Mål-CVR (%) | C10: 0.04 | D10: Mål conversion rate for betalte kanaler
B12: STRATEGISKE PARAMETRE
B13: LTV pr. kunde (kr.) | C13: 3600 | D13: Estimeret samlet livstidsværdi (gross). Default: 4.000 kWh/år × 0,45 kr margin × 2 år
B14: Bruttomarginal (%) | C14: 0.4 | D14: Kontributionsmargin pr. kunde efter variable omkostninger
B15: Gns. kundelevetid (mdr.) | C15: 24 | D15: Anvendes til CAC payback-beregning
B16: Mål CAC payback (mdr.) | C16: 12 | D16: Acceptabel tilbagebetalingstid for CAC
B17: Månedligt budgetloft (kr.) | C17: 200000 | D17: Månedligt marketing-budget (total spend target)
B19: STATUS-KODNING
B20: På sporet (grøn) | D20: På mål eller over
B21: Advarsel (orange) | D21: Inden for 10% af målet
B22: Off-track (rød) | D22: Mere end 10% fra mål
B24: FARVEKODNING (INPUT-ROLLER)
B25: CFO udfylder | D25: Partnerskabs-timer, løn, timepris, kontraktnøgletal
B26: CMO udfylder | D26: Kanal-spend, impressions, traffic, clients, Regningstjek-input
B27: Beregnet automatisk | D27: CVR, CAC, totaler, procenter
B29: TOT CAC (regnskab — CFO udfylder)
B30: Tot CAC 3M (kr.) | C30: 208
B31: Tot CAC 6M (kr.) | C31: 307
B32: Tot CAC 12M (kr.) | C32: 292

Sheet Input
B2: INPUT — MÅNEDLIGE MARKETINGDATA
B3: Kanal | C3: Metric | D3: 45565 | E3: 45596 | F3: 45626 | G3: 45657 | H3: 45688 | I3: 45716 | J3: 45747 | K3: 45777 | L3: 45808 | M3: 45838 | N3: 45869 | O3: 45900 | P3: 45930 | Q3: 45961 | R3: 45991 | S3: 46022 | T3: 46053 | U3: 46081 | V3: 46112 | W3: 46142 | X3: 46173 | Y3: 46203 | Z3: 46234 | AA3: 46265 | AB3: 46295 | AC3: 46326 | AD3: 46356 | AE3: 46387 | AF3: 46418 | AG3: 46446 | AH3: 46477
B4: ▪ PAID MARKETING
B5: Meta | C5: Cost (kr.) | D5: 7021 | E5: 10594 | F5: 18699 | G5: 19671 | H5: 159609 | I5: 39824 | J5: 47261 | K5: 30571 | L5: 42544 | M5: 27176 | N5: 25063 | O5: 23282 | P5: 17800 | Q5: 41600 | R5: 128946 | S5: 15444 | T5: 40422 | U5: 41894 | V5: 46639 | W5: 53431 | X5: 43242 | Y5: 44861 | Z5: 15618 | AA5: 16284
C6: Impressions | D6: 62418 | E6: 76931 | F6: 106459 | G6: 135899 | H6: 1483620 | I6: 315000 | J6: 370000 | K6: 254000 | L6: 322000 | M6: 80248 | N6: 197000 | O6: 225807 | P6: 169000 | Q6: 349000 | R6: 850326 | S6: 118000 | T6: 375500 | U6: 345000 | V6: 420000 | W6: 641000 | X6: 404000 | Y6: 545000 | Z6: 191437 | AA6: 188552
C7: Traffic | D7: 992 | E7: 1755 | F7: 3886 | G7: 6353 | H7: 43416 | I7: 7290 | J7: 7500 | K7: 3857 | L7: 5197 | M7: 3846 | N7: 4264 | O7: 3920 | P7: 3692 | Q7: 4033 | R7: 19468 | S7: 2517 | T7: 3512 | U7: 4514 | V7: 3885 | W7: 5760 | X7: 4669 | Y7: 3658 | Z7: 1392 | AA7: 2860
C8: Clients | D8: 26 | E8: 60 | F8: 69 | G8: 38 | H8: 282 | I8: 90 | J8: 84 | K8: 48 | L8: 58 | M8: 50 | N8: 51 | O8: 44 | P8: 31 | Q8: 39 | R8: 162 | S8: 45 | T8: 131 | U8: 150 | V8: 131 | W8: 120 | X8: 100 | Y8: 80 | Z8: 62 | AA8: 72
C9: CVR | D9: =IFERROR(D8/D7,0) | E9: =IFERROR(E8/E7,0) | F9: =IFERROR(F8/F7,0) | G9: =IFERROR(G8/G7,0) | H9: =IFERROR(H8/H7,0) | I9: =IFERROR(I8/I7,0) | J9: =IFERROR(J8/J7,0) | K9: =IFERROR(K8/K7,0) | ... AH9: =IFERROR(AH8/AH7,0)
C10: CAC (kr.) | D10: =IFERROR(D5/D8,0) | E10: =IFERROR(E5/E8,0) | F10: =IFERROR(F5/F8,0) | G10: =IFERROR(G5/G8,0) | H10: =IFERROR(H5/H8,0) | I10: =IFERROR(I5/I8,0) | J10: =IFERROR(J5/J8,0) | K10: =IFERROR(K5/K8,0) | ... AH10: =IFERROR(AH5/AH8,0)
B12: Google | C12: Cost (kr.) | D12: 3191 | E12: 2292 | F12: 1826 | G12: 3124 | H12: 7997 | I12: 4004 | T12: 6070 | U12: 5389 | V12: 5600 | W12: 6086 | X12: 6093 | Y12: 9860 | Z12: 6079 | AA12: 7371
C13: Impressions | D13: 60886 | E13: 29714 | F13: 29210 | G13: 87821 | H13: 376050 | I13: 19400 | T13: 2355 | U13: 3071 | V13: 19500 | W13: 8900 | X13: 12000 | Y13: 18000 | Z13: 10756 | AA13: 15817
C14: Traffic | D14: 1035 | E14: 550 | F14: 909 | G14: 2631 | H14: 3476 | I14: 849 | T14: 238 | U14: 302 | V14: 8271 | W14: 593 | X14: 705 | Y14: 910 | Z14: 522 | AA14: 801
C15: Clients | D15: 4 | E15: 8 | F15: 8 | G15: 20 | H15: 69 | I15: 13 | T15: 28 | U15: 32 | V15: 47 | W15: 41 | X15: 80 | Y15: 74 | Z15: 58 | AA15: 81
C16: CVR | D16: =IFERROR(D15/D14,0) | E16: =IFERROR(E15/E14,0) | F16: =IFERROR(F15/F14,0) | G16: =IFERROR(G15/G14,0) | H16: =IFERROR(H15/H14,0) | I16: =IFERROR(I15/I14,0) | J16: =IFERROR(J15/J14,0) | K16: =IFERROR(K15/K14,0) | ... AH16: =IFERROR(AH15/AH14,0)
C17: CAC (kr.) | D17: =IFERROR(D12/D15,0) | E17: =IFERROR(E12/E15,0) | F17: =IFERROR(F12/F15,0) | G17: =IFERROR(G12/G15,0) | H17: =IFERROR(H12/H15,0) | I17: =IFERROR(I12/I15,0) | J17: =IFERROR(J12/J15,0) | K17: =IFERROR(K12/K15,0) | ... AH17: =IFERROR(AH12/AH15,0)
B19: LinkedIn | C19: Cost (kr.) | H19: 14239 | X19: 0 | Y19: 0 | AA19: 0
C20: Impressions | H20: 302714 | X20: 0 | Y20: 0 | AA20: 0
C21: Traffic | H21: 5320 | X21: 0 | Y21: 0 | AA21: 0
C22: Clients | H22: 17 | X22: 0 | Y22: 0 | AA22: 0
C23: CVR | D23: =IFERROR(D22/D21,0) | E23: =IFERROR(E22/E21,0) | F23: =IFERROR(F22/F21,0) | G23: =IFERROR(G22/G21,0) | H23: =IFERROR(H22/H21,0) | I23: =IFERROR(I22/I21,0) | J23: =IFERROR(J22/J21,0) | K23: =IFERROR(K22/K21,0) | ... AH23: =IFERROR(AH22/AH21,0)
C24: CAC (kr.) | D24: =IFERROR(D19/D22,0) | E24: =IFERROR(E19/E22,0) | F24: =IFERROR(F19/F22,0) | G24: =IFERROR(G19/G22,0) | H24: =IFERROR(H19/H22,0) | I24: =IFERROR(I19/I22,0) | J24: =IFERROR(J19/J22,0) | K24: =IFERROR(K19/K22,0) | ... AH24: =IFERROR(AH19/AH22,0)
B26: Youtube | C26: Cost (kr.) | X26: 0 | Y26: 0 | AA26: 0
C27: Impressions | X27: 0 | Y27: 0 | AA27: 0
C28: Traffic | X28: 0 | Y28: 0 | AA28: 0
C29: Clients | X29: 0 | Y29: 0 | AA29: 0
C30: CVR | D30: =IFERROR(D29/D28,0) | E30: =IFERROR(E29/E28,0) | F30: =IFERROR(F29/F28,0) | G30: =IFERROR(G29/G28,0) | H30: =IFERROR(H29/H28,0) | I30: =IFERROR(I29/I28,0) | J30: =IFERROR(J29/J28,0) | K30: =IFERROR(K29/K28,0) | ... AH30: =IFERROR(AH29/AH28,0)
C31: CAC (kr.) | D31: =IFERROR(D26/D29,0) | E31: =IFERROR(E26/E29,0) | F31: =IFERROR(F26/F29,0) | G31: =IFERROR(G26/G29,0) | H31: =IFERROR(H26/H29,0) | I31: =IFERROR(I26/I29,0) | J31: =IFERROR(J26/J29,0) | K31: =IFERROR(K26/K29,0) | ... AH31: =IFERROR(AH26/AH29,0)
B33: Brand search | C33: Cost (kr.) | D33: 3453 | E33: 1526.33 | F33: 749 | G33: 486 | H33: 343518 | I33: 951 | J33: 924 | K33: 508 | L33: 622 | M33: 798 | N33: 780 | O33: 878 | P33: 881 | Q33: 927 | R33: 4772 | S33: 7440 | T33: 1679 | U33: 1509 | V33: 5600 | W33: 1142 | X33: 1355 | Y33: 1322 | Z33: 2037 | AA33: 2832
C34: Impressions | D34: 2078 | E34: 4690 | F34: 4792 | G34: 3207 | H34: 35011184 | I34: 5630 | J34: 6900 | K34: 5000 | L34: 6746 | M34: 6346 | P34: 6200 | Q34: 7200 | R34: 14700 | S34: 13500 | T34: 9616 | U34: 8806 | V34: 1400 | W34: 6470 | X34: 8300 | Y34: 8311 | Z34: 9641 | AA34: 10292
C35: Traffic | D35: 1169 | E35: 2686 | F35: 2950 | G35: 1870 | H35: 6369 | I35: 2400 | J35: 2974 | K35: 2040 | L35: 2223 | M35: 2194 | N35: 1900 | O35: 2105 | P35: 2210 | Q35: 2580 | R35: 4570 | S35: 3310 | T35: 4520 | U35: 3481 | V35: 9298 | W35: 2838 | X35: 3700 | Y35: 3761 | Z35: 4746 | AA35: 5042
C36: Clients | D36: 373 | E36: 283 | F36: 541 | G36: 430 | H36: 1050 | I36: 264 | J36: 209 | K36: 123 | L36: 151 | M36: 228 | N36: 154 | O36: 153 | P36: 166 | Q36: 165 | R36: 328 | S36: 346 | T36: 393 | U36: 500 | V36: 432 | W36: 387 | X36: 472 | Y36: 446 | Z36: 733 | AA36: 586
C37: CVR | D37: =IFERROR(D36/D35,0) | E37: =IFERROR(E36/E35,0) | F37: =IFERROR(F36/F35,0) | G37: =IFERROR(G36/G35,0) | H37: =IFERROR(H36/H35,0) | I37: =IFERROR(I36/I35,0) | J37: =IFERROR(J36/J35,0) | K37: =IFERROR(K36/K35,0) | ... AH37: =IFERROR(AH36/AH35,0)
C38: CAC (kr.) | D38: =IFERROR(D33/D36,0) | E38: =IFERROR(E33/E36,0) | F38: =IFERROR(F33/F36,0) | G38: =IFERROR(G33/G36,0) | H38: =IFERROR(H33/H36,0) | I38: =IFERROR(I33/I36,0) | J38: =IFERROR(J33/J36,0) | K38: =IFERROR(K33/K36,0) | ... AH38: =IFERROR(AH33/AH36,0)
B40: ▪ PARTNERSHIPS
B41: Influencers | C41: Cost (kr.) | H41: 16000 | X41: 0 | Y41: 0 | AA41: 0
C42: Impressions | H42: 300000 | X42: 0 | Y42: 0 | AA42: 0
C43: Traffic | X43: 0 | Y43: 0 | AA43: 0
C44: Clients | X44: 0 | Y44: 0 | AA44: 0
C45: CVR | D45: =IFERROR(D44/D43,0) | E45: =IFERROR(E44/E43,0) | F45: =IFERROR(F44/F43,0) | G45: =IFERROR(G44/G43,0) | H45: =IFERROR(H44/H43,0) | I45: =IFERROR(I44/I43,0) | J45: =IFERROR(J44/J43,0) | K45: =IFERROR(K44/K43,0) | ... AH45: =IFERROR(AH44/AH43,0)
C46: CAC (kr.) | D46: =IFERROR(D41/D44,0) | E46: =IFERROR(E41/E44,0) | F46: =IFERROR(F41/F44,0) | G46: =IFERROR(G41/G44,0) | H46: =IFERROR(H41/H44,0) | I46: =IFERROR(I41/I44,0) | J46: =IFERROR(J41/J44,0) | K46: =IFERROR(K41/K44,0) | ... AH46: =IFERROR(AH41/AH44,0)
...

Sheet Kommentarer
B2: KOMMENTARER — MÅNEDLIG NARRATIV
B3: Felt | C3: 45565 | D3: 45596 | E3: 45626 | F3: 45657 | G3: 45688 | H3: 45716 | I3: 45747 | J3: 45777 | K3: 45808 | L3: 45838 | M3: 45869 | N3: 45900 | O3: 45930 | P3: 45961 | Q3: 45991 | R3: 46022 | S3: 46053 | T3: 46081 | U3: 46112 | V3: 46142 | W3: 46173 | X3: 46203 | Y3: 46234 | Z3: 46265 | AA3: 46295 | AB3: 46326 | AC3: 46356 | AD3: 46387 | AE3: 46418 | AF3: 46446 | AG3: 46477
B4: EXECUTIVE SUMMARY
B5: Headline (1 sætning) | U5: Marts 2026: 1.286 nye kunder trods dårligere TÆNK-placering — affiliate-mix effektiviserede CAC til 191 kr (3M) og Meta-CAC faldt til 356 kr. | X5: Konverteringen stiger for anden måned i træk, og churn normaliseres efter maj-toppen. | Y5: Juli sætter rekord: 1.461 signups og 10 pct. konvertering midt i lavsæsonen.
B6: Hvad skete der (2-3 sætn.) | U6: Vi mistede TÆNK-topplaceringen efter metodeændring, men stor affiliate-indsats og ny partner AdLab kompenserede. Regningstjek-funnelen leverede 80 sign-ups med CAC på 468 kr — over mål, men bæredygtigt for produktdrevet vækst. Partnership-timer (14,6 af 700 kontrakterede) forbliver på plan. | X6: Sign-ups landede på 984, et forventet sæsonfald fra maj (1.035), men konverteringen steg igen — blended CVR ramte 6,4% mod 5,8% i maj. Google leverede 74 kunder til en CAC på 133 kr. (kanalens næstbedste måned), og Brand search fastholdt det høje niveau med 446 kunder. Churn faldt tilbage fra 2,6% til 2,2%, og vi rundede 13.318 aktive kunder (+582). | Y6: Juli blev den største måned i Altid Energis historie med 1.461 signups, klart over den tidligere rekord på 1.300 fra februar. Blended konvertering ramte 10,0 pct. (ny rekord), og blended CAC faldt til 131 kr. fra 157 kr. Brand search leverede 733 kunder (rekord), Google sin bedste konverteringsmåned (CVR 11,1 pct., CAC 105 kr.), og affiliates voksede til 334 kunder. Aktive kunder rundede 13.970 (15.267 målepunkter) med en nettotilvækst på 652, og churn holdt sig stabil på 2,2 pct.
B7: WINS — HVAD VIRKEDE
B8: Win 1 | U8: Affiliate-spor på tværs af alle elselskaber havde højest CVR — eltjek24 alene leverede 173 kunder. Dette er vores mest effektive betalte kanal aktuelt. | X8: Blended CVR ramte 6,4% — anden stigning i træk (3,8% → 5,8% → 6,4%) på trods af lavere trafik. | Y8: 1.461 signups, den højeste måned nogensinde (tidligere rekord 1.300 i februar), leveret midt i sommerlavsæsonen.
B9: Win 2 | U9: AdLab (ny affiliate-partner) nåede 31 kunder i første måned og 51 i første halvdel af april. Bevis på at vi kan skalere affiliate-porteføljen. | X9: Churn faldt fra maj's rekordhøje 2,6% til 2,2%, og aktive kunder rundede 13.318 (+582 netto). | Y9: Blended CVR ramte 10,0 pct. (rekord), og blended CAC faldt til 131 kr. fra 157 kr.
B10: Win 3 | U10: Meta CAC faldt fra 489 kr (jan) til 356 kr (marts) — creative refresh og mere præcis audience-targeting betaler sig. | X10: Google leverede 74 kunder (næstbedste måned nogensinde) til CAC 133 kr., og Brand search fastholdt momentum med 446 kunder. | Y10: Brand search satte rekord med 733 kunder, og Meta CAC faldt til 252 kr. fra 561 kr. efter optimeringen mod køb.
B11: WATCH-OUTS — OBS OMRÅDER
B12: Watch 1 | U12: TÆNK-placering tabt efter metodeændring. Har omarbejdet content + annoncering to gange — genetabler ikke automatisk inden marketing-plan 2026 er refreshet. | X12: Meta-CAC steg til 561 kr. (fra 432 kr.) — et normalt sæsonmønster, når efterspørgslen falder hen over sommeren. 80 kunder i lavsæsonen er reelt bedre end forventet. | Y12: Organisk trafik lå på 3.640 klik, fortsat sommerlavt. 389.000 eksponeringer viser dog stærk synlighed.
B13: Watch 2 | U13: Brand search CAC (528 kr) ligger 76% over mål. Søgevolumen for 'Altid Energi' er stigende, men konverteringsraten falder — hypotese: prissammenligninger trækker traffic væk. | X13: Organisk trafik faldt til 4.800 fra 7.180 — det er sommersæson, ikke SEO-tab. Der holdes øje med, at niveauet kommer tilbage.
B14: Watch 3 | U14: YouTube kanal genererer traffic men ingen kunder. 2.100 kr spend i marts uden sign-ups — enten pause eller retarget.
B15: INSIGHTS
B16: Key insight | U16: Vores bedste kanaler (affiliate, eltjek24) er dem hvor brugeren allerede er i pris-sammenlignings-mode. Brand-bygning (YouTube, TV2) underperformer på direkte CAC — bør måles på brand-lift ikke conversion. | X16: Konverteringsarbejdet på hjemmesiden virker: blended CVR er steget to måneder i træk (3,8% → 5,8% → 6,4%) på trods af lavere trafik. Volumen — ikke konvertering — er nu den primære begrænsning ind i sommerens lavsæson. | Y16: Efterspørgslen fra de 32.500 tvangsflyttede elkunder ramte direkte ned i et optimeret setup: rekordhøj brand search, stigende konvertering og faldende CAC på samme tid. Volumen kom tilbage langt tidligere end ventet i lavsæsonen.
B17: Markedsnote / konkurrence | U17: Dansk elmarked: Andel Energi og Norlys annoncerer nu også gebyr-fri tariffer. Vores USP udvandes — vi skal hurtigt finde den næste differentiering (forbrugsafregning-likviditet er vores mulighed). | X17: 32.500 danske elkunder tvangsflyttes fra deres nuværende leverandører. | Y17: 32.500 danske elkunder er tvangsflyttet fra deres leverandører i sommerens løb.
B18: NEXT MONTH FOCUS
B19: Prioritet 1 | U19: Refresh marketing-plan 2026 med forbrugsafregning-likviditet som ny USP. Owner: Mikkel. Deadline: maj. | X19: Lancere Bliss Budget-samarbejdet (landingpage + signup-flow live 1. juli).
B20: Prioritet 2 | U20: Skalér AdLab og aktivér yderligere 2 affiliate-partnere. Test budget-shift fra YouTube → affiliate. Owner: Performance-team. Deadline: april. | X20: Lancere Savier-samarbejdet.
B21: Prioritet 3 | U21: Sæt brand-lift måling op for YouTube + TV2 (brand search-volumen som proxy). Owner: Analytics. Deadline: april. | X21: Holde øje med performance henover ferieperioden.

Sheet Rapport
B2: ALTID ENERGI — MARKETING PERFORMANCE REPORT
B3: Danmarks eneste gebyrfri elselskab — strøm til indkøbspris | V3: =TEXT(Input!V$3,"mmmm yyyy")&" · Prepared "&TEXT(TODAY(),"mmm d, yyyy")
B6: SIGN-UPS | G6: BLENDED CAC | L6: CAC PAYBACK | Q6: LTV : CAC | V6: MARKETING SPEND | AA6: BLENDED CVR
B7: =Input!V111 | G7: =Input!V112 | L7: =IFERROR(Input!V112/(ltv*margin_pct/customer_lifetime),0) | Q7: =IFERROR((ltv*margin_pct)/Input!V112,0) | V7: =Input!V110 | AA7: =Input!V116
B8: =IF(Input!V111>=Input!U111,"ON TRACK",IF(Input!V111>=Input!U111*0.9,"WATCH","OFF-TRACK")) | G8: =IF(Input!V112<=CAC_TARGET,"ON TRACK",IF(Input!V112<=CAC_TARGET*1.1,"WATCH","OFF-TRACK")) | L8: – | Q8: =IF(IFERROR((ltv*margin_pct)/Input!V112,0)>=3,"ON TRACK",IF(IFERROR((ltv*margin_pct)/Input!V112,0)>=2,"WATCH","OFF-TRACK")) | V8: – | AA8: =IF(Input!V116>=CVR_TARGET,"ON TRACK",IF(Input!V116>=CVR_TARGET*0.9,"WATCH","OFF-TRACK"))
B9: =IFERROR(Input!V111/Input!U111-1,0) | G9: =IFERROR(Input!V112/Input!U112-1,0) | L9: =IFERROR(Input!V112/(ltv*margin_pct/customer_lifetime)-Input!U112/(ltv*margin_pct/customer_lifetime),0) | Q9: =IFERROR((ltv*margin_pct)/Input!V112-(ltv*margin_pct)/Input!U112,0) | V9: =IFERROR(Input!V110/Input!U110-1,0) | AA9: =IFERROR(Input!V116-Input!U116,0)
B10: Total new customers this month | G10: Total spend / total sign-ups | L10: CAC recovered via gross margin | Q10: Target ≥ 3.0x | V10: Month-to-date total spend | AA10: Total sign-ups / total visitors
B13: 12-MONTH TREND — SIGN-UPS & BLENDED CAC
B34: EXECUTIVE NARRATIVE
B35: WINS | L35: WATCH-OUTS | V35: NEXT MONTH FOCUS
B36: =IFERROR(Kommentarer!U8,"") | L36: =IFERROR(Kommentarer!U12,"") | V36: =IFERROR(Kommentarer!U19,"")
B40: =IFERROR(Kommentarer!U9,"") | L40: =IFERROR(Kommentarer!U13,"") | V40: =IFERROR(Kommentarer!U20,"")
B44: =IFERROR(Kommentarer!U10,"") | L44: =IFERROR(Kommentarer!U14,"") | V44: =IFERROR(Kommentarer!U21,"")
B52: CHANNEL PERFORMANCE & UNIT ECONOMICS
B54: Channel | H54: Spend (3M) | L54: % of paid | N54: Sign-ups (3M) | Q54: CVR (3M) | T54: CAC (3M) | W54: vs Target | Z54: Status
B55: Meta | H55: =SUM(Input!T5:V5) | L55: =IFERROR(SUM(Input!T5:V5)/SUM(Input!T117:V117),0) | N55: =SUM(Input!T8:V8) | Q55: =IFERROR(AVERAGEIFS(Input!T9:V9,Input!T9:V9,">0"),0) | T55: =IFERROR(SUM(Input!T5:V5)/SUM(Input!T8:V8),0) | W55: =IFERROR(IFERROR(SUM(Input!T5:V5)/SUM(Input!T8:V8),0)/CAC_TARGET-1,0) | Z55: =IF(IFERROR(SUM(Input!T5:V5)/SUM(Input!T8:V8),0)=0,"NO DATA",IF(IFERROR(SUM(Input!T5:V5)/SUM(Input!T8:V8),0)<=CAC_TARGET,"ON TRACK",IF(IFERROR(SUM(Input!T5:V5)/SUM(Input!T8:V8),0)<=CAC_TARGET*1.15,"WATCH","OFF-TRACK")))
B56: Google | H56: =SUM(Input!T12:V12) | L56: =IFERROR(SUM(Input!T12:V12)/SUM(Input!T117:V117),0) | N56: =SUM(Input!T15:V15) | Q56: =IFERROR(AVERAGEIFS(Input!T16:V16,Input!T16:V16,">0"),0) | T56: =IFERROR(SUM(Input!T12:V12)/SUM(Input!T15:V15),0) | W56: =IFERROR(IFERROR(SUM(Input!T12:V12)/SUM(Input!T15:V15),0)/CAC_TARGET-1,0) | Z56: =IF(IFERROR(SUM(Input!T12:V12)/SUM(Input!T15:V15),0)=0,"NO DATA",IF(IFERROR(SUM(Input!T12:V12)/SUM(Input!T15:V15),0)<=CAC_TARGET,"ON TRACK",IF(IFERROR(SUM(Input!T12:V12)/SUM(Input!T15:V15),0)<=CAC_TARGET*1.15,"WATCH","OFF-TRACK")))
B57: Brand search | H57: =SUM(Input!T33:V33) | L57: =IFERROR(SUM(Input!T33:V33)/SUM(Input!T117:V117),0) | N57: =SUM(Input!T36:V36) | Q57: =IFERROR(AVERAGEIFS(Input!T37:V37,Input!T37:V37,">0"),0) | T57: =IFERROR(SUM(Input!T33:V33)/SUM(Input!T36:V36),0) | W57: =IFERROR(IFERROR(SUM(Input!T33:V33)/SUM(Input!T36:V36),0)/CAC_TARGET-1,0) | Z57: =IF(IFERROR(SUM(Input!T33:V33)/SUM(Input!T36:V36),0)=0,"NO DATA",IF(IFERROR(SUM(Input!T33:V33)/SUM(Input!T36:V36),0)<=CAC_TARGET,"ON TRACK",IF(IFERROR(SUM(Input!T33:V33)/SUM(Input!T36:V36),0)<=CAC_TARGET*1.15,"WATCH","OFF-TRACK")))
B58: LinkedIn | H58: =SUM(Input!T19:V19) | L58: =IFERROR(SUM(Input!T19:V19)/SUM(Input!T117:V117),0) | N58: =SUM(Input!T22:V22) | Q58: =IFERROR(AVERAGEIFS(Input!T23:V23,Input!T23:V23,">0"),0) | T58: =IFERROR(SUM(Input!T19:V19)/SUM(Input!T22:V22),0) | W58: =IFERROR(IFERROR(SUM(Input!T19:V19)/SUM(Input!T22:V22),0)/CAC_TARGET-1,0) | Z58: =IF(IFERROR(SUM(Input!T19:V19)/SUM(Input!T22:V22),0)=0,"NO DATA",IF(IFERROR(SUM(Input!T19:V19)/SUM(Input!T22:V22),0)<=CAC_TARGET,"ON TRACK",IF(IFERROR(SUM(Input!T19:V19)/SUM(Input!T22:V22),0)<=CAC_TARGET*1.15,"WATCH","OFF-TRACK")))
B59: Youtube | H59: =SUM(Input!T26:V26) | L59: =IFERROR(SUM(Input!T26:V26)/SUM(Input!T117:V117),0) | N59: =SUM(Input!T29:V29) | Q59: =IFERROR(AVERAGEIFS(Input!T30:V30,Input!T30:V30,">0"),0) | T59: =IFERROR(SUM(Input!T26:V26)/SUM(Input!T29:V29),0) | W59: =IFERROR(IFERROR(SUM(Input!T26:V26)/SUM(Input!T29:V29),0)/CAC_TARGET-1,0) | Z59: =IF(IFERROR(SUM(Input!T26:V26)/SUM(Input!T29:V29),0)=0,"NO DATA",IF(IFERROR(SUM(Input!T26:V26)/SUM(Input!T29:V29),0)<=CAC_TARGET,"ON TRACK",IF(IFERROR(SUM(Input!T26:V26)/SUM(Input!T29:V29),0)<=CAC_TARGET*1.15,"WATCH","OFF-TRACK")))
B60: Affiliates | H60: =SUM(Input!T48:V48) | L60: =IFERROR(SUM(Input!T48:V48)/SUM(Input!T117:V117),0) | N60: =SUM(Input!T51:V51) | Q60: =IFERROR(AVERAGEIFS(Input!T52:V52,Input!T52:V52,">0"),0) | T60: =IFERROR(SUM(Input!T48:V48)/SUM(Input!T51:V51),0) | W60: =IFERROR(IFERROR(SUM(Input!T48:V48)/SUM(Input!T51:V51),0)/CAC_TARGET-1,0) | Z60: =IF(IFERROR(SUM(Input!T48:V48)/SUM(Input!T51:V51),0)=0,"NO DATA",IF(IFERROR(SUM(Input!T48:V48)/SUM(Input!T51:V51),0)<=CAC_TARGET,"ON TRACK",IF(IFERROR(SUM(Input!T48:V48)/SUM(Input!T51:V51),0)<=CAC_TARGET*1.15,"WATCH","OFF-TRACK")))
B61: Influencers | H61: =SUM(Input!T41:V41) | L61: =IFERROR(SUM(Input!T41:V41)/SUM(Input!T117:V117),0) | N61: =SUM(Input!T44:V44) | Q61: =IFERROR(AVERAGEIFS(Input!T45:V45,Input!T45:V45,">0"),0) | T61: =IFERROR(SUM(Input!T41:V41)/SUM(Input!T44:V44),0) | W61: =IFERROR(IFERROR(SUM(Input!T41:V41)/SUM(Input!T44:V44),0)/CAC_TARGET-1,0) | Z61: =IF(IFERROR(SUM(Input!T41:V41)/SUM(Input!T44:V44),0)=0,"NO DATA",IF(IFERROR(SUM(Input!T41:V41)/SUM(Input!T44:V44),0)<=CAC_TARGET,"ON TRACK",IF(IFERROR(SUM(Input!T41:V41)/SUM(Input!T44:V44),0)<=CAC_TARGET*1.15,"WATCH","OFF-TRACK")))
B62: TV2 | H62: =SUM(Input!T71:V71) | L62: =IFERROR(SUM(Input!T71:V71)/SUM(Input!T117:V117),0) | N62: =SUM(Input!T74:V74) | Q62: =IFERROR(AVERAGEIFS(Input!T75:V75,Input!T75:V75,">0"),0) | T62: =IFERROR(SUM(Input!T71:V71)/SUM(Input!T74:V74),0) | W62: =IFERROR(IFERROR(SUM(Input!T71:V71)/SUM(Input!T74:V74),0)/CAC_TARGET-1,0) | Z62: =IF(IFERROR(SUM(Input!T71:V71)/SUM(Input!T74:V74),0)=0,"NO DATA",IF(IFERROR(SUM(Input!T71:V71)/SUM(Input!T74:V74),0)<=CAC_TARGET,"ON TRACK",IF(IFERROR(SUM(Input!T71:V71)/SUM(Input!T74:V74),0)<=CAC_TARGET*1.15,"WATCH","OFF-TRACK")))
B63: Werner (LinkedIn) | H63: =SUM(Input!T56:V56) | L63: =IFERROR(SUM(Input!T56:V56)/SUM(Input!T117:V117),0) | N63: =SUM(Input!T59:V59) | Q63: =IFERROR(AVERAGEIFS(Input!T60:V60,Input!T60:V60,">0"),0) | T63: =IFERROR(SUM(Input!T56:V56)/SUM(Input!T59:V59),0) | W63: =IFERROR(IFERROR(SUM(Input!T56:V56)/SUM(Input!T59:V59),0)/CAC_TARGET-1,0) | Z63: =IF(IFERROR(SUM(Input!T56:V56)/SUM(Input!T59:V59),0)=0,"NO DATA",IF(IFERROR(SUM(Input!T56:V56)/SUM(Input!T59:V59),0)<=CAC_TARGET,"ON TRACK",IF(IFERROR(SUM(Input!T56:V56)/SUM(Input!T59:V59),0)<=CAC_TARGET*1.15,"WATCH","OFF-TRACK")))
B64: Other (internal) | H64: =SUM(Input!T63:V63) | L64: =IFERROR(SUM(Input!T63:V63)/SUM(Input!T117:V117),0) | N64: =SUM(Input!T66:V66) | Q64: =IFERROR(AVERAGEIFS(Input!T67:V67,Input!T67:V67,">0"),0) | T64: =IFERROR(SUM(Input!T63:V63)/SUM(Input!T66:V66),0) | W64: =IFERROR(IFERROR(SUM(Input!T63:V63)/SUM(Input!T66:V66),0)/CAC_TARGET-1,0) | Z64: =IF(IFERROR(SUM(Input!T63:V63)/SUM(Input!T66:V66),0)=0,"NO DATA",IF(IFERROR(SUM(Input!T63:V63)/SUM(Input!T66:V66),0)<=CAC_TARGET,"ON TRACK",IF(IFERROR(SUM(Input!T63:V63)/SUM(Input!T66:V66),0)<=CAC_TARGET*1.15,"WATCH","OFF-TRACK")))
B65: TOTAL — ALL PAID + PARTNER | H65: =SUM(Input!T117:V117)+SUM(Input!T120:V120) | L65: 1 | N65: =SUM(Input!T118:V118)+SUM(Input!T121:V121) | Q65: =IFERROR((SUM(Input!T118:V118)+SUM(Input!T121:V121))/SUM(Input!T114:V114),0) | T65: =IFERROR((SUM(Input!T117:V117)+SUM(Input!T120:V120))/(SUM(Input!T118:V118)+SUM(Input!T121:V121)),0) | W65: =IFERROR(IFERROR((SUM(Input!T117:V117)+SUM(Input!T120:V120))/(SUM(Input!T118:V118)+SUM(Input!T121:V121)),0)/CAC_TARGET-1,0) | Z65: TOTAL
B67: CAC per channel (last 3 months) | Q67: Spend mix — 3-month window
B83: Meta | C83: Google | D83: Brand search | E83: LinkedIn | F83: Youtube | G83: Affiliates | H83: Influencers | I83: TV2 | J83: Werner (LinkedIn) | K83: Other (internal)
B84: =IFERROR(SUM(Input!T5:V5)/SUM(Input!T8:V8),0) | C84: =IFERROR(SUM(Input!T12:V12)/SUM(Input!T15:V15),0) | D84: =IFERROR(SUM(Input!T33:V33)/SUM(Input!T36:V36),0) | E84: =IFERROR(SUM(Input!T19:V19)/SUM(Input!T22:V22),0) | F84: =IFERROR(SUM(Input!T26:V26)/SUM(Input!T29:V29),0) | G84: =IFERROR(SUM(Input!T48:V48)/SUM(Input!T51:V51),0) | H84: =IFERROR(SUM(Input!T41:V41)/SUM(Input!T44:V44),0) | I84: =IFERROR(SUM(Input!T71:V71)/SUM(Input!T74:V74),0) | J84: =IFERROR(SUM(Input!T56:V56)/SUM(Input!T59:V59),0) | K84: =IFERROR(SUM(Input!T63:V63)/SUM(Input!T66:V66),0)
B85: Meta | C85: Google | D85: Brand search | E85: LinkedIn | F85: Youtube | G85: Affiliates | H85: Influencers | I85: TV2 | J85: Werner (LinkedIn) | K85: Other (internal)
B86: =SUM(Input!T5:V5) | C86: =SUM(Input!T12:V12) | D86: =SUM(Input!T33:V33) | E86: =SUM(Input!T19:V19) | F86: =SUM(Input!T26:V26) | G86: =SUM(Input!T48:V48) | H86: =SUM(Input!T41:V41) | I86: =SUM(Input!T71:V71) | J86: =SUM(Input!T56:V56) | K86: =SUM(Input!T63:V63)
B88: UNIT ECONOMICS — CURRENT MONTH
B89: LTV (Gross) | I89: Contribution | P89: Blended CAC | X89: CAC Payback
B90: – | I90: – | P90: =Input!V112 | X90: =IFERROR(Input!V112/(ltv*margin_pct/customer_lifetime),0)
B92: Per-customer lifetime value (gross) | I92: LTV × gross margin | P92: This month (vs target 300 kr) | X92: (CAC) / (LTV × Margin / Lifetime)
B94: Assumptions (Konfig): LTV=3,600 kr · Gross margin=40% · Customer lifetime=24 months · Payback target≤12 months · Target CAC=300 kr. Adjust in Konfig to update model.
B96: ="LTV:CAC ratio = "&TEXT(IFERROR((ltv*margin_pct)/Input!V112,0),"0.00")&"x · "&IF(IFERROR((ltv*margin_pct)/Input!V112,0)>=3,"Healthy unit economics — scale marketing.","Below 3.0x — optimize CAC before scaling spend.")
B102: GROWTH ENGINES & COMMENTARY
B104: PARTNERSHIP — MELIORA VENTURES | Q104: REGNINGSTJEK — PLG FUNNEL
B106: Sign-ups (3M) | F106: Partner CAC (3M) | J106: Hours used (Total) | N106: % Completion | Q106: Uploads (3M) | U106: New customers (3M) | Y106: Regningstjek CAC (3M)
...
